Workbook

Sheet Votes
A1: Department | B1: Nominee | C1: President | D1: Year | E1: Senate Action Date | F1: Congress | G1: Outcome | H1: Vote Type | I1: Yeas | J1: Nays | K1: Present | L1: Not Voting | M1: VP Tie-Break | N1: Margin (Yeas - Nays) | O1: Yea Share | P1: Senate Roll Call No. | Q1: Voteview ID | R1: Not-Voting Source | S1: Notes
A2: State | B2: Elihu Root | C2: T. Roosevelt | D2: 1905 | G2: Confirmed | H2: No roll call recorded | N2: =IF(I2="","",I2-J2) | O2: =IF(I2="","",I2/(I2+J2))
A3: State | B3: Robert Bacon | C3: T. Roosevelt | D3: 1909 | G3: Confirmed | H3: No roll call recorded | N3: =IF(I3="","",I3-J3) | O3: =IF(I3="","",I3/(I3+J3))
A4: State | B4: Philander C. Knox | C4: Taft | D4: 1909 | G4: Confirmed | H4: No roll call recorded | N4: =IF(I4="","",I4-J4) | O4: =IF(I4="","",I4/(I4+J4))
A5: State | B5: William Jennings Bryan | C5: Wilson | D5: 1913 | G5: Confirmed | H5: No roll call recorded | N5: =IF(I5="","",I5-J5) | O5: =IF(I5="","",I5/(I5+J5))
A6: State | B6: Robert Lansing | C6: Wilson | D6: 1915 | G6: Confirmed | H6: No roll call recorded | N6: =IF(I6="","",I6-J6) | O6: =IF(I6="","",I6/(I6+J6))
A7: State | B7: Bainbridge Colby | C7: Wilson | D7: 1920 | G7: Confirmed | H7: No roll call recorded | N7: =IF(I7="","",I7-J7) | O7: =IF(I7="","",I7/(I7+J7))
A8: State | B8: Charles Evans Hughes | C8: Harding | D8: 1921 | G8: Confirmed | H8: No roll call recorded | N8: =IF(I8="","",I8-J8) | O8: =IF(I8="","",I8/(I8+J8))
A9: State | B9: Frank B. Kellogg | C9: Coolidge | D9: 1925 | G9: Confirmed | H9: No roll call recorded | N9: =IF(I9="","",I9-J9) | O9: =IF(I9="","",I9/(I9+J9)) | S9: A 1923 roll call (75-9) on Kellogg is for his nomination as Ambassador to the UK, not Secretary of State.
A10: State | B10: Henry L. Stimson | C10: Hoover | D10: 1929 | G10: Confirmed | H10: No roll call recorded | N10: =IF(I10="","",I10-J10) | O10: =IF(I10="","",I10/(I10+J10))
A11: State | B11: Cordell Hull | C11: F. Roosevelt | D11: 1933 | G11: Confirmed | H11: No roll call recorded | N11: =IF(I11="","",I11-J11) | O11: =IF(I11="","",I11/(I11+J11))
A12: State | B12: Edward R. Stettinius Jr. | C12: F. Roosevelt | D12: 1944 | E12: 16406 | F12: 78 | G12: Confirmed | H12: Roll call | I12: 68 | J12: 1 | K12: 0 | L12: 26 | N12: =IF(I12="","",I12-J12) -> 67 | O12: =IF(I12="","",I12/(I12+J12)) -> 0.98550725 | Q12: RS0780206 | R12: Voteview member codes (not yea/nay) | S12: Voteview spells the name 'STETINIUS'. Member codes total 95, implying one vacant seat.
A13: State | B13: James F. Byrnes | C13: Truman | D13: 1945 | G13: Confirmed | H13: No roll call recorded | N13: =IF(I13="","",I13-J13) | O13: =IF(I13="","",I13/(I13+J13))
A14: State | B14: George C. Marshall | C14: Truman | D14: 1947 | G14: Confirmed | H14: No roll call recorded | N14: =IF(I14="","",I14-J14) | O14: =IF(I14="","",I14/(I14+J14))
A15: State | B15: Dean Acheson | C15: Truman | D15: 1949 | E15: 17916 | F15: 81 | G15: Confirmed | H15: Roll call | I15: 83 | J15: 6 | K15: 0 | L15: 7 | N15: =IF(I15="","",I15-J15) -> 77 | O15: =IF(I15="","",I15/(I15+J15)) -> 0.93258427 | Q15: RS0810006 | R15: Derived: 96 seats - yeas - nays (see Notes)
A16: State | B16: John Foster Dulles | C16: Eisenhower | D16: 1953 | G16: Confirmed | H16: No roll call recorded | N16: =IF(I16="","",I16-J16) | O16: =IF(I16="","",I16/(I16+J16))
A17: State | B17: Christian A. Herter | C17: Eisenhower | D17: 1959 | E17: 21661 | F17: 86 | G17: Confirmed | H17: Roll call | I17: 93 | J17: 0 | K17: 0 | L17: 5 | N17: =IF(I17="","",I17-J17) -> 93 | O17: =IF(I17="","",I17/(I17+J17)) -> 1 | Q17: RS0860033 | R17: Voteview member codes (not yea/nay) | S17: 98-seat Senate (Alaska admitted Jan. 1959; Hawaii not until Aug. 1959).
A18: State | B18: Dean Rusk | C18: Kennedy | D18: 1961 | G18: Confirmed | H18: No roll call recorded | N18: =IF(I18="","",I18-J18) | O18: =IF(I18="","",I18/(I18+J18))
A19: State | B19: William P. Rogers | C19: Nixon | D19: 1969 | G19: Confirmed | H19: No roll call recorded | N19: =IF(I19="","",I19-J19) | O19: =IF(I19="","",I19/(I19+J19))
A20: State | B20: Henry A. Kissinger | C20: Nixon | D20: 1973 | E20: 26928 | F20: 93 | G20: Confirmed | H20: Roll call | I20: 78 | J20: 7 | K20: 0 | L20: 15 | N20: =IF(I20="","",I20-J20) -> 71 | O20: =IF(I20="","",I20/(I20+J20)) -> 0.91764706 | Q20: RS0930394 | R20: Voteview member codes (not yea/nay)
A21: State | B21: Cyrus R. Vance | C21: Carter | D21: 1977 | E21: 28145 | F21: 95 | G21: Confirmed | H21: Voice vote | N21: =IF(I21="","",I21-J21) | O21: =IF(I21="","",I21/(I21+J21))
A22: State | B22: Edmund S. Muskie | C22: Carter | D22: 1980 | E22: 29348 | F22: 96 | G22: Confirmed | H22: Roll call | I22: 94 | J22: 2 | K22: 1 | L22: 3 | N22: =IF(I22="","",I22-J22) -> 92 | O22: =IF(I22="","",I22/(I22+J22)) -> 0.97916667 | P22: 102 | Q22: RS0960610 | R22: Voteview member codes (not yea/nay) | S22: One senator recorded as present (Voteview code 8).
A23: State | B23: Alexander M. Haig Jr. | C23: Reagan | D23: 1981 | E23: 29607 | F23: 97 | G23: Confirmed | H23: Roll call | I23: 93 | J23: 6 | K23: 0 | L23: 1 | N23: =IF(I23="","",I23-J23) -> 87 | O23: =IF(I23="","",I23/(I23+J23)) -> 0.93939394 | P23: 3 | Q23: RS0970003 | R23: Voteview member codes (not yea/nay)
A24: State | B24: George P. Shultz | C24: Reagan | D24: 1982 | E24: 30147 | F24: 97 | G24: Confirmed | H24: Roll call | I24: 97 | J24: 0 | K24: 0 | L24: 3 | N24: =IF(I24="","",I24-J24) -> 97 | O24: =IF(I24="","",I24/(I24+J24)) -> 1 | P24: 216 | Q24: RS0970713 | R24: Voteview member codes (not yea/nay) | S24: Voteview spells the name 'SCHULTZ'.
A25: State | B25: James A. Baker III | C25: G.H.W. Bush | D25: 1989 | E25: 32533 | F25: 101 | G25: Confirmed | H25: Roll call | I25: 99 | J25: 0 | K25: 0 | L25: 1 | N25: =IF(I25="","",I25-J25) -> 99 | O25: =IF(I25="","",I25/(I25+J25)) -> 1 | P25: 1 | R25: Senate roll call record (senate.gov)
A26: State | B26: Lawrence S. Eagleburger | C26: G.H.W. Bush | D26: 1992 | G26: Recess appointment | H26: No Senate vote | N26: =IF(I26="","",I26-J26) | O26: =IF(I26="","",I26/(I26+J26)) | S26: Served on a recess appointment; the Senate took no action on the nomination.
A27: State | B27: Warren Christopher | C27: Clinton | D27: 1993 | E27: 33989 | F27: 103 | G27: Confirmed | H27: Voice vote | N27: =IF(I27="","",I27-J27) | O27: =IF(I27="","",I27/(I27+J27))
A28: State | B28: Madeleine K. Albright | C28: Clinton | D28: 1997 | E28: 35452 | F28: 105 | G28: Confirmed | H28: Roll call | I28: 99 | J28: 0 | K28: 0 | L28: 1 | N28: =IF(I28="","",I28-J28) -> 99 | O28: =IF(I28="","",I28/(I28+J28)) -> 1 | P28: 1 | R28: Senate roll call record (senate.gov)
A29: State | B29: Colin L. Powell | C29: G.W. Bush | D29: 2001 | E29: 36911 | F29: 107 | G29: Confirmed | H29: Voice vote | N29: =IF(I29="","",I29-J29) | O29: =IF(I29="","",I29/(I29+J29))
A30: State | B30: Condoleezza Rice | C30: G.W. Bush | D30: 2005 | E30: 38378 | F30: 109 | G30: Confirmed | H30: Roll call | I30: 85 | J30: 13 | K30: 0 | L30: 2 | N30: =IF(I30="","",I30-J30) -> 72 | O30: =IF(I30="","",I30/(I30+J30)) -> 0.86734694 | P30: 2 | R30: Senate roll call record (senate.gov)
A31: State | B31: Hillary Rodham Clinton | C31: Obama | D31: 2009 | E31: 39834 | F31: 111 | G31: Confirmed | H31: Roll call | I31: 94 | J31: 2 | K31: 0 | L31: 2 | N31: =IF(I31="","",I31-J31) -> 92 | O31: =IF(I31="","",I31/(I31+J31)) -> 0.97916667 | P31: 6 | R31: Senate roll call record (senate.gov) | S31: Two seats vacant on the vote date (94+2+2=98).
A32: State | B32: John F. Kerry | C32: Obama | D32: 2013 | E32: 41303 | F32: 113 | G32: Confirmed | H32: Roll call | I32: 94 | J32: 3 | K32: 1 | L32: 2 | N32: =IF(I32="","",I32-J32) -> 91 | O32: =IF(I32="","",I32/(I32+J32)) -> 0.96907216 | P32: 5 | R32: Senate roll call record (senate.gov) | S32: Kerry voted 'present' on his own nomination.
A33: State | B33: Rex W. Tillerson | C33: Trump | D33: 2017 | E33: 42767 | F33: 115 | G33: Confirmed | H33: Roll call | I33: 56 | J33: 43 | K33: 0 | L33: 1 | N33: =IF(I33="","",I33-J33) -> 13 | O33: =IF(I33="","",I33/(I33+J33)) -> 0.56565657 | P33: 36 | R33: Senate roll call record (senate.gov)
A34: State | B34: Mike Pompeo | C34: Trump | D34: 2018 | E34: 43216 | F34: 115 | G34: Confirmed | H34: Roll call | I34: 57 | J34: 42 | K34: 0 | L34: 1 | N34: =IF(I34="","",I34-J34) -> 15 | O34: =IF(I34="","",I34/(I34+J34)) -> 0.57575758 | P34: 84 | R34: Senate roll call record (senate.gov)
A35: State | B35: Antony J. Blinken | C35: Biden | D35: 2021 | E35: 44222 | F35: 117 | G35: Confirmed | H35: Roll call | I35: 78 | J35: 22 | K35: 0 | L35: 0 | N35: =IF(I35="","",I35-J35) -> 56 | O35: =IF(I35="","",I35/(I35+J35)) -> 0.78 | P35: 7 | R35: Senate roll call record (senate.gov)
A36: State | B36: Marco Rubio | C36: Trump | D36: 2025 | E36: 45677 | F36: 119 | G36: Confirmed | H36: Roll call | I36: 99 | J36: 0 | K36: 0 | L36: 0 | N36: =IF(I36="","",I36-J36) -> 99 | O36: =IF(I36="","",I36/(I36+J36)) -> 1 | P36: 8 | R36: Senate roll call record (senate.gov) | S36: 99 senators: Rubio's own Florida seat was vacant.
A37: Treasury | B37: Leslie M. Shaw | C37: T. Roosevelt | D37: 1902 | G37: Confirmed | H37: No roll call recorded | N37: =IF(I37="","",I37-J37) | O37: =IF(I37="","",I37/(I37+J37))
A38: Treasury | B38: George B. Cortelyou | C38: T. Roosevelt | D38: 1907 | G38: Confirmed | H38: No roll call recorded | N38: =IF(I38="","",I38-J38) | O38: =IF(I38="","",I38/(I38+J38))
A39: Treasury | B39: Franklin MacVeagh | C39: Taft | D39: 1909 | G39: Confirmed | H39: No roll call recorded | N39: =IF(I39="","",I39-J39) | O39: =IF(I39="","",I39/(I39+J39))
A40: Treasury | B40: William G. McAdoo | C40: Wilson | D40: 1913 | G40: Confirmed | H40: No roll call recorded | N40: =IF(I40="","",I40-J40) | O40: =IF(I40="","",I40/(I40+J40))
...

Sheet Summary
A1: Department | B1: Nominations | C1: Recorded Roll Calls | D1: Share with Roll Call | E1: Roll Calls with 10+ Nays | F1: Average Yea Share (roll calls) | G1: Total Nays Cast | H1: Coverage
A2: State | B2: =COUNTIFS(Votes!$A:$A,A2) -> 35 | C2: =COUNTIFS(Votes!$A:$A,A2,Votes!$H:$H,"Roll call") -> 16 | D2: =IF(B2=0,"",C2/B2) -> 0.45714286 | E2: =COUNTIFS(Votes!$A:$A,A2,Votes!$J:$J,">=10") -> 4 | F2: =IFERROR(AVERAGEIFS(Votes!$O:$O,Votes!$A:$A,A2,Votes!$H:$H,"Roll call"),"") -> 0.90570619 | G2: =SUMIFS(Votes!$J:$J,Votes!$A:$A,A2) -> 147 | H2: 1900-2025
A3: Treasury | B3: =COUNTIFS(Votes!$A:$A,A3) -> 37 | C3: =COUNTIFS(Votes!$A:$A,A3,Votes!$H:$H,"Roll call") -> 12 | D3: =IF(B3=0,"",C3/B3) -> 0.32432432 | E3: =COUNTIFS(Votes!$A:$A,A3,Votes!$J:$J,">=10") -> 5 | F3: =IFERROR(AVERAGEIFS(Votes!$O:$O,Votes!$A:$A,A3,Votes!$H:$H,"Roll call"),"") -> 0.86650748 | G3: =SUMIFS(Votes!$J:$J,Votes!$A:$A,A3) -> 156 | H3: 1900-2025
A4: Defense | B4: =COUNTIFS(Votes!$A:$A,A4) -> 31 | C4: =COUNTIFS(Votes!$A:$A,A4,Votes!$H:$H,"Roll call") -> 19 | D4: =IF(B4=0,"",C4/B4) -> 0.61290323 | E4: =COUNTIFS(Votes!$A:$A,A4,Votes!$J:$J,">=10") -> 4 | F4: =IFERROR(AVERAGEIFS(Votes!$O:$O,Votes!$A:$A,A4,Votes!$H:$H,"Roll call"),"") -> 0.89860496 | G4: =SUMIFS(Votes!$J:$J,Votes!$A:$A,A4) -> 185 | H4: 1947-2025
A5: All | B5: =SUM(B2:B4) -> 103 | C5: =SUM(C2:C4) -> 47 | D5: =IF(B5=0,"",C5/B5) -> 0.45631068 | E5: =SUM(E2:E4) -> 13 | F5: =IFERROR(AVERAGEIFS(Votes!$O:$O,Votes!$H:$H,"Roll call"),"") -> 0.8928273 | G5: =SUM(G2:G4) -> 488
A7: Averages use the Yea Share column, which counts only yeas and nays. Hegseth's 50-50 tie is counted as 50%.

Sheet Sources & Notes
A1: Topic | B1: Note
A2: Scope | B2: One row per nomination that reached the Senate: Secretary of State and Secretary of the Treasury from 1900, Secretary of Defense from its creation in 1947. Officials who carried over from a previous administration without a new nomination (e.g., Brady 1989, Gates 2009) are not separate rows. John Hay (State, appointed 1898) and Lyman Gage (Treasury, appointed 1897) predate the window.
A3: No roll call recorded | B3: For most nominations before the late 1970s the Senate confirmed without a recorded vote (voice vote or unanimous consent). For 1900-1976 these were identified by sweeping every Senate appointment and confirmation roll call in Voteview, Congress by Congress, not only by searching nominee names. Voteview misspells several names (STETINIUS, SCHULTZ), so name searches alone miss votes. Voteview includes pre-1929 executive-session roll calls, e.g., Kellogg's 1923 ambassadorship vote.
A4: Vote type, 1977-2025 | B4: Taken from the Senate's cabinet-nomination tables for each administration (Carter through Trump, 2nd term), which distinguish roll call, voice vote and unanimous consent.
A5: Yeas / Nays | B5: 1977 onward: Senate cabinet tables, which agree with Voteview in every case checked. Before 1977: Voteview roll-call records.
A6: Not Voting: 1989 onward | B6: Official counts from each Senate roll-call vote page (senate.gov LIS). These reflect vacancies. For example, Clinton and Geithner (Jan. 2009) were voted on with two seats empty.
A7: Not Voting: before 1989 | B7: The Senate publishes no roll-call pages before 1989, so these come from Voteview's member-level vote codes: everyone seated who did not cast a yea or nay (paired, announced, absent). In every case except the 81st Congress, the codes sum to the seats filled on the vote date. The 81st Congress (Acheson 1949, Marshall 1950) is anomalous in Voteview: its code totals exceed 96 because members who served at any point in that Congress are included. For those two votes, Not Voting is computed as 96 - yeas - nays, which assumes no vacancies. Verify against the Congressional Record if exact figures matter.
A8: Present | B8: Recorded separately where it occurred: Kerry 2013 (voted present on his own nomination) and Muskie 1980.
A9: Hegseth (2025) | B9: The Senate divided 50-50 and Vice President Vance cast the tie-breaking vote. Yeas records senators only (50); VP Tie-Break = Yea. The Senate's cabinet table shows the result as 51-50.
A10: Senate Roll Call No. | B10: Session-specific roll call number as published by the Senate (1977 onward). Voteview ID is Voteview's rollcall identifier (RS + Congress + sequence), shown where Voteview was the source.
A11: Year / Senate Action Date | B11: Year is the year of appointment. Senate Action Date is given where it was verified from a Senate or Voteview record; it is left blank for early nominations confirmed without a roll call.
A12: Sources | B12: U.S. Senate, cabinet nomination tables (senate.gov/legislative/nominations/, Carter_cabinet.htm through Trump_47_cabinet.htm); U.S. Senate roll call vote pages (senate.gov/legislative/LIS/roll_call_votes/); Lewis, Jeffrey B., et al. Voteview: Congressional Roll-Call Votes Database (voteview.com); U.S. Treasury, Prior Secretaries (home.treasury.gov). Compiled September 2026.
